[2025-09-06T16:43:46.874+0000] {local_task_job_runner.py:120} INFO - ::group::Pre task execution logs
[2025-09-06T16:43:46.906+0000] {taskinstance.py:2076} INFO - Dependencies all met for dep_context=non-requeueable deps ti=<TaskInstance: dbt_transformations.dbt_deps manual__2025-09-06T16:39:55.642526+00:00 [queued]>
[2025-09-06T16:43:46.913+0000] {taskinstance.py:2076} INFO - Dependencies all met for dep_context=requeueable deps ti=<TaskInstance: dbt_transformations.dbt_deps manual__2025-09-06T16:39:55.642526+00:00 [queued]>
[2025-09-06T16:43:46.913+0000] {taskinstance.py:2306} INFO - Starting attempt 1 of 1
[2025-09-06T16:43:46.923+0000] {taskinstance.py:2330} INFO - Executing <Task(BashOperator): dbt_deps> on 2025-09-06 16:39:55.642526+00:00
[2025-09-06T16:43:46.932+0000] {logging_mixin.py:188} WARNING - /home/***/.local/lib/python3.12/site-packages/***/task/task_runner/standard_task_runner.py:62 DeprecationWarning: This process (pid=4417) is multi-threaded, use of fork() may lead to deadlocks in the child.
[2025-09-06T16:43:46.934+0000] {standard_task_runner.py:64} INFO - Started process 4421 to run task
[2025-09-06T16:43:46.932+0000] {standard_task_runner.py:90} INFO - Running: ['***', 'tasks', 'run', 'dbt_transformations', 'dbt_deps', 'manual__2025-09-06T16:39:55.642526+00:00', '--job-id', '96', '--raw', '--subdir', 'DAGS_FOLDER/dbt_transformations.py', '--cfg-path', '/tmp/tmpuhk3nuv_']
[2025-09-06T16:43:46.936+0000] {standard_task_runner.py:91} INFO - Job 96: Subtask dbt_deps
[2025-09-06T16:43:46.996+0000] {task_command.py:426} INFO - Running <TaskInstance: dbt_transformations.dbt_deps manual__2025-09-06T16:39:55.642526+00:00 [running]> on host dd8e0e853e24
[2025-09-06T16:43:47.065+0000] {taskinstance.py:2648} INFO - Exporting env vars: AIRFLOW_CTX_DAG_OWNER='***' AIRFLOW_CTX_DAG_ID='dbt_transformations' AIRFLOW_CTX_TASK_ID='dbt_deps' AIRFLOW_CTX_EXECUTION_DATE='2025-09-06T16:39:55.642526+00:00' AIRFLOW_CTX_TRY_NUMBER='1' AIRFLOW_CTX_DAG_RUN_ID='manual__2025-09-06T16:39:55.642526+00:00'
[2025-09-06T16:43:47.066+0000] {taskinstance.py:430} INFO - ::endgroup::
[2025-09-06T16:43:47.090+0000] {subprocess.py:63} INFO - Tmp dir root location: /tmp
[2025-09-06T16:43:47.091+0000] {subprocess.py:75} INFO - Running command: ['/usr/bin/bash', '-c', 'export PATH="$PATH:/home/***/.local/bin" && cd /opt/***/dbt && DBT_PROFILES_DIR="/opt/***/dbt" dbt deps']
[2025-09-06T16:43:47.100+0000] {subprocess.py:86} INFO - Output:
[2025-09-06T16:43:49.675+0000] {subprocess.py:93} INFO - [0m16:43:49  Running with dbt=1.10.11
[2025-09-06T16:43:49.820+0000] {subprocess.py:93} INFO - [0m16:43:49  Encountered an error:
[2025-09-06T16:43:49.820+0000] {subprocess.py:93} INFO - [Errno 2] No such file or directory: 'dbt_packages/dbt_utils'
[2025-09-06T16:43:49.827+0000] {subprocess.py:93} INFO - [0m16:43:49  Traceback (most recent call last):
[2025-09-06T16:43:49.827+0000] {subprocess.py:93} INFO -   File "/home/***/.local/lib/python3.12/site-packages/dbt/cli/requires.py", line 178, in wrapper
[2025-09-06T16:43:49.828+0000] {subprocess.py:93} INFO -     result, success = func(*args, **kwargs)
[2025-09-06T16:43:49.829+0000] {subprocess.py:93} INFO -                       ^^^^^^^^^^^^^^^^^^^^^
[2025-09-06T16:43:49.829+0000] {subprocess.py:93} INFO -   File "/home/***/.local/lib/python3.12/site-packages/dbt/cli/requires.py", line 128, in wrapper
[2025-09-06T16:43:49.829+0000] {subprocess.py:93} INFO -     return func(*args, **kwargs)
[2025-09-06T16:43:49.830+0000] {subprocess.py:93} INFO -            ^^^^^^^^^^^^^^^^^^^^^
[2025-09-06T16:43:49.830+0000] {subprocess.py:93} INFO -   File "/home/***/.local/lib/python3.12/site-packages/dbt/cli/requires.py", line 254, in wrapper
[2025-09-06T16:43:49.830+0000] {subprocess.py:93} INFO -     return func(*args, **kwargs)
[2025-09-06T16:43:49.831+0000] {subprocess.py:93} INFO -            ^^^^^^^^^^^^^^^^^^^^^
[2025-09-06T16:43:49.831+0000] {subprocess.py:93} INFO -   File "/home/***/.local/lib/python3.12/site-packages/dbt/cli/requires.py", line 303, in wrapper
[2025-09-06T16:43:49.832+0000] {subprocess.py:93} INFO -     return func(*args, **kwargs)
[2025-09-06T16:43:49.833+0000] {subprocess.py:93} INFO -            ^^^^^^^^^^^^^^^^^^^^^
[2025-09-06T16:43:49.834+0000] {subprocess.py:93} INFO -   File "/home/***/.local/lib/python3.12/site-packages/dbt/cli/main.py", line 461, in deps
[2025-09-06T16:43:49.834+0000] {subprocess.py:93} INFO -     results = task.run()
[2025-09-06T16:43:49.835+0000] {subprocess.py:93} INFO -               ^^^^^^^^^^
[2025-09-06T16:43:49.835+0000] {subprocess.py:93} INFO -   File "/home/***/.local/lib/python3.12/site-packages/dbt/task/deps.py", line 231, in run
[2025-09-06T16:43:49.835+0000] {subprocess.py:93} INFO -     system.rmtree(self.project.packages_install_path)
[2025-09-06T16:43:49.836+0000] {subprocess.py:93} INFO -   File "/home/***/.local/lib/python3.12/site-packages/dbt_common/clients/system.py", line 715, in rmtree
[2025-09-06T16:43:49.836+0000] {subprocess.py:93} INFO -     return shutil.rmtree(path, onerror=chmod_and_retry)
[2025-09-06T16:43:49.836+0000] {subprocess.py:93} INFO -            ^^^^^^^^^^^^^^^^^^^^^^^^^^^^^^^^^^^^^^^^^^^^
[2025-09-06T16:43:49.837+0000] {subprocess.py:93} INFO -   File "/usr/local/lib/python3.12/shutil.py", line 759, in rmtree
[2025-09-06T16:43:49.837+0000] {subprocess.py:93} INFO -     _rmtree_safe_fd(stack, onexc)
[2025-09-06T16:43:49.838+0000] {subprocess.py:93} INFO -   File "/usr/local/lib/python3.12/shutil.py", line 703, in _rmtree_safe_fd
[2025-09-06T16:43:49.839+0000] {subprocess.py:93} INFO -     onexc(func, path, err)
[2025-09-06T16:43:49.839+0000] {subprocess.py:93} INFO -   File "/usr/local/lib/python3.12/shutil.py", line 750, in onexc
[2025-09-06T16:43:49.841+0000] {subprocess.py:93} INFO -     return onerror(func, path, exc_info)
[2025-09-06T16:43:49.841+0000] {subprocess.py:93} INFO -            ^^^^^^^^^^^^^^^^^^^^^^^^^^^^^
[2025-09-06T16:43:49.841+0000] {subprocess.py:93} INFO -   File "/usr/local/lib/python3.12/shutil.py", line 700, in _rmtree_safe_fd
[2025-09-06T16:43:49.842+0000] {subprocess.py:93} INFO -     onexc(os.unlink, fullname, err)
[2025-09-06T16:43:49.843+0000] {subprocess.py:93} INFO -   File "/usr/local/lib/python3.12/shutil.py", line 750, in onexc
[2025-09-06T16:43:49.843+0000] {subprocess.py:93} INFO -     return onerror(func, path, exc_info)
[2025-09-06T16:43:49.844+0000] {subprocess.py:93} INFO -            ^^^^^^^^^^^^^^^^^^^^^^^^^^^^^
[2025-09-06T16:43:49.845+0000] {subprocess.py:93} INFO -   File "/usr/local/lib/python3.12/shutil.py", line 698, in _rmtree_safe_fd
[2025-09-06T16:43:49.846+0000] {subprocess.py:93} INFO -     os.unlink(entry.name, dir_fd=topfd)
[2025-09-06T16:43:49.846+0000] {subprocess.py:93} INFO - FileNotFoundError: [Errno 2] No such file or directory: 'dbt_packages/dbt_utils'
[2025-09-06T16:43:49.846+0000] {subprocess.py:93} INFO - 
[2025-09-06T16:43:51.669+0000] {subprocess.py:97} INFO - Command exited with return code 2
[2025-09-06T16:43:51.674+0000] {taskinstance.py:441} INFO - ::group::Post task execution logs
[2025-09-06T16:43:51.720+0000] {taskinstance.py:2905} ERROR - Task failed with exception
Traceback (most recent call last):
  File "/home/airflow/.local/lib/python3.12/site-packages/airflow/models/taskinstance.py", line 465, in _execute_task
    result = _execute_callable(context=context, **execute_callable_kwargs)
             ^^^^^^^^^^^^^^^^^^^^^^^^^^^^^^^^^^^^^^^^^^^^^^^^^^^^^^^^^^^^^
  File "/home/airflow/.local/lib/python3.12/site-packages/airflow/models/taskinstance.py", line 432, in _execute_callable
    return execute_callable(context=context, **execute_callable_kwargs)
           ^^^^^^^^^^^^^^^^^^^^^^^^^^^^^^^^^^^^^^^^^^^^^^^^^^^^^^^^^^^^
  File "/home/airflow/.local/lib/python3.12/site-packages/airflow/models/baseoperator.py", line 401, in wrapper
    return func(self, *args, **kwargs)
           ^^^^^^^^^^^^^^^^^^^^^^^^^^^
  File "/home/airflow/.local/lib/python3.12/site-packages/airflow/operators/bash.py", line 243, in execute
    raise AirflowException(
airflow.exceptions.AirflowException: Bash command failed. The command returned a non-zero exit code 2.
[2025-09-06T16:43:51.729+0000] {taskinstance.py:1206} INFO - Marking task as FAILED. dag_id=dbt_transformations, task_id=dbt_deps, run_id=manual__2025-09-06T16:39:55.642526+00:00, execution_date=20250906T163955, start_date=20250906T164346, end_date=20250906T164351
[2025-09-06T16:43:51.757+0000] {standard_task_runner.py:110} ERROR - Failed to execute job 96 for task dbt_deps (Bash command failed. The command returned a non-zero exit code 2.; 4421)
[2025-09-06T16:43:51.813+0000] {local_task_job_runner.py:243} INFO - Task exited with return code 1
[2025-09-06T16:43:51.866+0000] {taskinstance.py:3503} INFO - 0 downstream tasks scheduled from follow-on schedule check
[2025-09-06T16:43:51.882+0000] {local_task_job_runner.py:222} INFO - ::endgroup::
